<?xml version="1.0"?>
<robot name="third_arm">

  <!-- Third Arm has 5 joints, base link kept trans_xyz with the environment link -->

  <link name="environment_x">
    <visual>
      <origin xyz="0 0 0" rpy ="0 0 0"/>
      <material name="Gray">
       <color rgba="0.3 0.3 0.3 1.0"/>
      </material>   
      <geometry>
        <cylinder length="0.0" radius="0.0"/>
      </geometry>
    </visual>
    <collision>
      <origin xyz="0 0 0" rpy ="0 0 0"/>
      <material name="Gray">
       <color rgba="0.3 0.3 0.3 1.0"/>
      </material>   
      <geometry>
        <cylinder length="0.0" radius="0.0"/>
      </geometry>
    </collision>
    <inertial>
            <mass value="1.0"/>
            <inertia ixx="0.015" iyy="0.0375" izz="0.0375" ixy="0" ixz="0" iyz="0"/>
        </inertial>    
  </link>

  <link name="environment_y">
    <visual>
    <origin xyz="0 0 0" rpy ="0 0 0"/>
      <material name="Gray">
       <color rgba="0.3 0.3 0.3 1.0"/>
      </material>   
      <geometry>
        <cylinder length="0.0" radius="0.0"/>
      </geometry>
    </visual>
  </link>

  <joint name="env_x" type="prismatic">
  <origin xyz="0 0 0" rpy="0 0 0" />
  <axis xyz="1 0 0"/>    
  <limit lower="-1" upper="1" effort="100" velocity="10"/>    
    <parent link="environment_x"/>
    <child link="environment_y"/>
  </joint>

  <link name="environment_z">
    <visual>
    <origin xyz="0 0 0" rpy ="0 0 0"/>
      <material name="Gray">
       <color rgba="0.3 0.3 0.3 1.0"/>
      </material>   
      <geometry>
        <cylinder length="0.0" radius="0.0"/>
      </geometry>
    </visual>
  </link>


  <joint name="env_y" type="prismatic">
  <origin xyz="0 0 0" rpy="0 0 0" />
  <axis xyz="0 1 0"/>        
  <limit lower="-1" upper="1" effort="100" velocity="10"/>    
    <parent link="environment_y"/>
    <child link="environment_z"/>
  </joint>

  <link name="base_link">
    <visual>
		<origin xyz="0 0 0" rpy ="0 0  0"/>
      <material name="Gray">
       <color rgba="0.3 0.3 0.3 1.0"/>
      </material> 	
      <geometry>
        <cylinder length="0.05" radius="0.05"/>
      </geometry>
    </visual>
  </link>

  <joint name="env_z_to_base" type="prismatic">
  <origin xyz="0 0 0" rpy="0 0 0" />
  <axis xyz="0 0 1"/>        
  <limit lower="-1" upper="1" effort="100" velocity="10"/>      
    <parent link="environment_z"/>
    <child link="base_link"/>
  </joint>


  <link name="base_motor">
  	<inertial>
  		<origin xyz="0 0 0" rpy ="0 0 0"/>
  		<mass value="1"/>
  		<inertia ixx="100"  ixy="0"  ixz="0" iyy="100" iyz="0" izz="100" />
  	</inertial>
    <visual>
		<origin xyz="0 0 0" rpy ="0 0  0"/>
      <material name="Yellow">
       <color rgba="1.0 1.0 0.0 1.0"/>
      </material> 	
      <geometry>
        <cylinder length="0.08" radius="0.05"/>
      </geometry>
    </visual>
  </link>


  <joint name="horizontal_panning" type="revolute">
  	<axis xyz="0 0 1"/>
  	<limit lower="-3.14" upper="3.14" effort="10" velocity="3.14"/>
  	<origin xyz="0 0 0.0" rpy="0 0 -1.5708" />
    <parent link="base_link"/>
    <child link="base_motor"/>
  </joint>


  <link name="lift_motor">
  	<inertial>
  		<origin xyz="0 0 0" rpy ="0 0 0"/>
  		<mass value="1"/>
  		<inertia ixx="100"  ixy="0"  ixz="0" iyy="100" iyz="0" izz="100" />
  	</inertial>
    <visual>
		<origin xyz="0 0 0" rpy ="0 0 0"/>
      <material name="Yellow">
       <color rgba="1.0 1.0 0.0 1.0"/>
      </material> 	
      <geometry>
        <cylinder length="0.1" radius="0.05"/>
      </geometry>
    </visual>
  </link>

  <joint name="vertical_pitching" type="revolute">
  	<axis xyz="0 0 1"/>
  	<limit lower="0" upper="1.5708" effort="10" velocity="0.314"/>
  	<origin xyz="0 0 -0.08" rpy="1.5708 3.14159 1.5708" />
    <parent link="base_motor"/>
    <child link="lift_motor"/>
  </joint>

  <link name="extend_link1">
    <visual>
		<origin xyz="0 0.0 0" rpy ="0 0 0"/>
      <material name="Blue">
       <color rgba="0 0.0 1.0 0.4"/>
      </material> 	
      <geometry>
        <box size="0.1 0.2 0.1"/>
      </geometry>
    </visual>
  </link>

  <joint name="motor2_to_extend1" type="fixed">
  	<origin xyz="0 0.1 0" rpy="0 0 0" />
    <parent link="lift_motor"/>
    <child link="extend_link1"/>
  </joint>

  <link name="extend_link2">
    <visual>
		<origin xyz="0 0 0" rpy ="0 0 0"/>
      <material name="Blue2">
       <color rgba="0.2 0.2 1.0 1.0"/>
      </material> 	
      <geometry>
        <box size="0.07 .33 .07"/>
      </geometry>
    </visual>
  </link>
  
  <joint name="length_extension" type="prismatic">
  	<axis xyz="0 1 0"/>
  	<limit lower="0" upper="0.12" effort="10" velocity="5"/>
  	<origin xyz="0 0.065 0" rpy="0 0 0" />
    <parent link="extend_link1"/>
    <child link="extend_link2"/>
  </joint>


  <link name="wrist_rotation_motor">
  	<inertial>
  		<origin xyz="0 0 0" rpy =" 1.5708 0  0"/>
  		<mass value="1"/>
  		<inertia ixx="100"  ixy="0"  ixz="0" iyy="100" iyz="0" izz="100" />
  	</inertial>
    <visual>
		<origin xyz="0 0 0" rpy ="1.5708 0 0"/>
      <material name="Yellow">
       <color rgba="1.0 1.0 0.0 1.0"/>
      </material> 	
      <geometry>
        <cylinder length="0.09" radius="0.03"/>
      </geometry>
    </visual>
  </link>

  <joint name="wrist_rotation" type="revolute">
  	<axis xyz="0 1 0"/>
  	<limit lower="-3.14" upper="3.14" effort="5" velocity="0.5"/>
  	<origin xyz="0 0.165 0" rpy="0 0 0" />
    <parent link="extend_link2"/>
    <child link="wrist_rotation_motor"/>
  </joint>

  <link name="wrist_tilt_motor">
    <inertial>
      <origin xyz="0 0 0" rpy ="0 0 0"/>
      <mass value="1"/>
      <inertia ixx="100"  ixy="0"  ixz="0" iyy="100" iyz="0" izz="100" />
    </inertial>
    <visual>
    <origin xyz="0 0 0" rpy ="0 0 0"/>
      <material name="Yellow">
       <color rgba="1.0 1.0 0.0 1.0"/>
      </material>   
      <geometry>
        <cylinder length="0.05" radius="0.03"/>
      </geometry>
    </visual>
  </link>

  <joint name="wrist_pitching" type="revolute">
    <axis xyz="0 0 1"/>
    <limit lower="0" upper="3.14159" effort="5" velocity="0.5"/>
    <origin xyz="0 0.045 0" rpy="0 0 -1.5708" />
    <parent link="wrist_rotation_motor"/>
    <child link="wrist_tilt_motor"/>
  </joint>

  <link name="wrist_plate">
    <visual>
		<origin xyz="0 0 0" rpy ="0 0 0"/>
      <material name="Blue">
       <color rgba="0.0 0.0 1.0 1.0"/>
      </material> 	
      <geometry>
        <box size="0.07 .035 .07"/>
      </geometry>
    </visual>
  </link>

  <joint name="wrist_tilt_motor_to_plate" type="fixed">
  	<origin xyz="0 0.0175 0" rpy="0 0 0" />
    <parent link="wrist_tilt_motor"/>
    <child link="wrist_plate"/>
  </joint>

  <link name="gripper_plate">
    <visual>
    <origin xyz="0.0 0 0" rpy ="0 0 0"/>
      <material name="Blue">
       <color rgba="0.0 0.0 1.0 1.0"/>
      </material>   
      <geometry>
        <box size=".1 .03 .03"/>
      </geometry>
    </visual>
  </link>

  <joint name="wrist_plate_to_gripper_plate" type="fixed">
    <origin xyz="0 0.0675 0" rpy="1.5708 0 1.5708" />
    <parent link="wrist_plate"/>
    <child link="gripper_plate"/>
  </joint>

  <link name="gripper_end_point">
    <visual>
    <origin xyz="0 0 0" rpy ="0 0 0"/>
      <material name="Blue">
       <color rgba="0.0 0.0 1.0 1.0"/>
      </material>   
      <geometry>
        <box size=".0 .0 .0"/>
      </geometry>
    </visual>
  </link>

<joint name="gripper_end_point" type="fixed">
    <origin xyz="0.05 0 0" rpy="0 0 0" />
    <parent link="gripper_plate"/>
    <child link="gripper_end_point"/>
  </joint>
</robot>